Traceback (most recent call last):
  File "/Users/prathyusha/Desktop/pranathi/airflow_cnn_pipeline_final/airflow_test_env/lib/python3.7/site-packages/psutil/_common.py", line 447, in wrapper
    ret = self._cache[fun]
AttributeError: _cache

During handling of the above exception, another exception occurred:

Traceback (most recent call last):
  File "/Users/prathyusha/Desktop/pranathi/airflow_cnn_pipeline_final/airflow_test_env/lib/python3.7/site-packages/psutil/_psosx.py", line 344, in wrapper
    return fun(self, *args, **kwargs)
  File "/Users/prathyusha/Desktop/pranathi/airflow_cnn_pipeline_final/airflow_test_env/lib/python3.7/site-packages/psutil/_common.py", line 450, in wrapper
    return fun(self)
  File "/Users/prathyusha/Desktop/pranathi/airflow_cnn_pipeline_final/airflow_test_env/lib/python3.7/site-packages/psutil/_psosx.py", line 397, in _get_kinfo_proc
    ret = cext.proc_kinfo_oneshot(self.pid)
ProcessLookupError: [Errno 3] assume no such process (originated from sysctl (len == 0))

During handling of the above exception, another exception occurred:

Traceback (most recent call last):
  File "/Users/prathyusha/Desktop/pranathi/airflow_cnn_pipeline_final/airflow_test_env/lib/python3.7/site-packages/psutil/__init__.py", line 354, in _init
    self.create_time()
  File "/Users/prathyusha/Desktop/pranathi/airflow_cnn_pipeline_final/airflow_test_env/lib/python3.7/site-packages/psutil/__init__.py", line 710, in create_time
    self._create_time = self._proc.create_time()
  File "/Users/prathyusha/Desktop/pranathi/airflow_cnn_pipeline_final/airflow_test_env/lib/python3.7/site-packages/psutil/_psosx.py", line 344, in wrapper
    return fun(self, *args, **kwargs)
  File "/Users/prathyusha/Desktop/pranathi/airflow_cnn_pipeline_final/airflow_test_env/lib/python3.7/site-packages/psutil/_psosx.py", line 500, in create_time
    return self._get_kinfo_proc()[kinfo_proc_map['ctime']]
  File "/Users/prathyusha/Desktop/pranathi/airflow_cnn_pipeline_final/airflow_test_env/lib/python3.7/site-packages/psutil/_psosx.py", line 349, in wrapper
    raise NoSuchProcess(self.pid, self._name)
psutil.NoSuchProcess: psutil.NoSuchProcess process no longer exists (pid=31507)

During handling of the above exception, another exception occurred:

Traceback (most recent call last):
  File "airflow_test_env/bin/airflow", line 8, in <module>
    sys.exit(main())
  File "/Users/prathyusha/Desktop/pranathi/airflow_cnn_pipeline_final/airflow_test_env/lib/python3.7/site-packages/airflow/__main__.py", line 40, in main
    args.func(args)
  File "/Users/prathyusha/Desktop/pranathi/airflow_cnn_pipeline_final/airflow_test_env/lib/python3.7/site-packages/airflow/cli/cli_parser.py", line 48, in command
    return func(*args, **kwargs)
  File "/Users/prathyusha/Desktop/pranathi/airflow_cnn_pipeline_final/airflow_test_env/lib/python3.7/site-packages/airflow/utils/cli.py", line 89, in wrapper
    return f(*args, **kwargs)
  File "/Users/prathyusha/Desktop/pranathi/airflow_cnn_pipeline_final/airflow_test_env/lib/python3.7/site-packages/airflow/cli/commands/webserver_command.py", line 480, in webserver
    monitor_gunicorn(gunicorn_master_proc.pid)
  File "/Users/prathyusha/Desktop/pranathi/airflow_cnn_pipeline_final/airflow_test_env/lib/python3.7/site-packages/airflow/cli/commands/webserver_command.py", line 452, in monitor_gunicorn
    'webserver', 'reload_on_plugin_change', fallback=False
  File "/Users/prathyusha/Desktop/pranathi/airflow_cnn_pipeline_final/airflow_test_env/lib/python3.7/site-packages/airflow/cli/commands/webserver_command.py", line 212, in start
    self._check_workers()
  File "/Users/prathyusha/Desktop/pranathi/airflow_cnn_pipeline_final/airflow_test_env/lib/python3.7/site-packages/airflow/cli/commands/webserver_command.py", line 258, in _check_workers
    num_workers_running = self._get_num_workers_running()
  File "/Users/prathyusha/Desktop/pranathi/airflow_cnn_pipeline_final/airflow_test_env/lib/python3.7/site-packages/airflow/cli/commands/webserver_command.py", line 147, in _get_num_workers_running
    workers = psutil.Process(self.gunicorn_master_proc.pid).children()
  File "/Users/prathyusha/Desktop/pranathi/airflow_cnn_pipeline_final/airflow_test_env/lib/python3.7/site-packages/psutil/__init__.py", line 326, in __init__
    self._init(pid)
  File "/Users/prathyusha/Desktop/pranathi/airflow_cnn_pipeline_final/airflow_test_env/lib/python3.7/site-packages/psutil/__init__.py", line 367, in _init
    raise NoSuchProcess(pid, None, msg)
psutil.NoSuchProcess: psutil.NoSuchProcess no process found with pid 31507
