[2021-03-25 14:18:49,355] {taskinstance.py:851} INFO - Dependencies all met for <TaskInstance: EDGAR-Inference-Pipeline.DownloadDataFromCloud 2021-03-25T00:00:00+00:00 [queued]>
[2021-03-25 14:18:49,370] {taskinstance.py:851} INFO - Dependencies all met for <TaskInstance: EDGAR-Inference-Pipeline.DownloadDataFromCloud 2021-03-25T00:00:00+00:00 [queued]>
[2021-03-25 14:18:49,370] {taskinstance.py:1042} INFO - 
--------------------------------------------------------------------------------
[2021-03-25 14:18:49,370] {taskinstance.py:1043} INFO - Starting attempt 1 of 1
[2021-03-25 14:18:49,370] {taskinstance.py:1044} INFO - 
--------------------------------------------------------------------------------
[2021-03-25 14:18:49,377] {taskinstance.py:1063} INFO - Executing <Task(PythonOperator): DownloadDataFromCloud> on 2021-03-25T00:00:00+00:00
[2021-03-25 14:18:49,380] {standard_task_runner.py:52} INFO - Started process 2867 to run task
[2021-03-25 14:18:49,389] {standard_task_runner.py:76} INFO - Running: ['airflow', 'tasks', 'run', 'EDGAR-Inference-Pipeline', 'DownloadDataFromCloud', '2021-03-25T00:00:00+00:00', '--job-id', '4', '--pool', 'default_pool', '--raw', '--subdir', 'DAGS_FOLDER/edgar_inference.py', '--cfg-path', '/var/folders/_j/s8vbc0cs1fvgclq8hnvtq1wm0000gn/T/tmp9l50dte1', '--error-file', '/var/folders/_j/s8vbc0cs1fvgclq8hnvtq1wm0000gn/T/tmphlfpxbcs']
[2021-03-25 14:18:49,391] {standard_task_runner.py:77} INFO - Job 4: Subtask DownloadDataFromCloud
[2021-03-25 14:18:49,440] {logging_mixin.py:104} INFO - Running <TaskInstance: EDGAR-Inference-Pipeline.DownloadDataFromCloud 2021-03-25T00:00:00+00:00 [running]> on host prathyushas-mbp.home
[2021-03-25 14:18:49,481] {taskinstance.py:1257} INFO - Exporting the following env vars:
AIRFLOW_CTX_DAG_OWNER=airflow
AIRFLOW_CTX_DAG_ID=EDGAR-Inference-Pipeline
AIRFLOW_CTX_TASK_ID=DownloadDataFromCloud
AIRFLOW_CTX_EXECUTION_DATE=2021-03-25T00:00:00+00:00
AIRFLOW_CTX_DAG_RUN_ID=scheduled__2021-03-25T00:00:00+00:00
[2021-03-25 14:18:49,499] {taskinstance.py:1455} ERROR - <urlopen error [Errno 61] Connection refused>
Traceback (most recent call last):
  File "/Library/Frameworks/Python.framework/Versions/3.7/lib/python3.7/urllib/request.py", line 1350, in do_open
    encode_chunked=req.has_header('Transfer-encoding'))
  File "/Library/Frameworks/Python.framework/Versions/3.7/lib/python3.7/http/client.py", line 1262, in request
    self._send_request(method, url, body, headers, encode_chunked)
  File "/Library/Frameworks/Python.framework/Versions/3.7/lib/python3.7/http/client.py", line 1308, in _send_request
    self.endheaders(body, encode_chunked=encode_chunked)
  File "/Library/Frameworks/Python.framework/Versions/3.7/lib/python3.7/http/client.py", line 1257, in endheaders
    self._send_output(message_body, encode_chunked=encode_chunked)
  File "/Library/Frameworks/Python.framework/Versions/3.7/lib/python3.7/http/client.py", line 1028, in _send_output
    self.send(msg)
  File "/Library/Frameworks/Python.framework/Versions/3.7/lib/python3.7/http/client.py", line 968, in send
    self.connect()
  File "/Library/Frameworks/Python.framework/Versions/3.7/lib/python3.7/http/client.py", line 940, in connect
    (self.host,self.port), self.timeout, self.source_address)
  File "/Library/Frameworks/Python.framework/Versions/3.7/lib/python3.7/socket.py", line 728, in create_connection
    raise err
  File "/Library/Frameworks/Python.framework/Versions/3.7/lib/python3.7/socket.py", line 716, in create_connection
    sock.connect(sa)
ConnectionRefusedError: [Errno 61] Connection refused

During handling of the above exception, another exception occurred:

Traceback (most recent call last):
  File "/Users/prathyusha/Desktop/pranathi/CSYE7245-Spring2021-Labs/transcript-simulated-api/airflow/edgar4_env/lib/python3.7/site-packages/airflow/models/taskinstance.py", line 1112, in _run_raw_task
    self._prepare_and_execute_task_with_callbacks(context, task)
  File "/Users/prathyusha/Desktop/pranathi/CSYE7245-Spring2021-Labs/transcript-simulated-api/airflow/edgar4_env/lib/python3.7/site-packages/airflow/models/taskinstance.py", line 1285, in _prepare_and_execute_task_with_callbacks
    result = self._execute_task(context, task_copy)
  File "/Users/prathyusha/Desktop/pranathi/CSYE7245-Spring2021-Labs/transcript-simulated-api/airflow/edgar4_env/lib/python3.7/site-packages/airflow/models/taskinstance.py", line 1315, in _execute_task
    result = task_copy.execute(context=context)
  File "/Users/prathyusha/Desktop/pranathi/CSYE7245-Spring2021-Labs/transcript-simulated-api/airflow/edgar4_env/lib/python3.7/site-packages/airflow/operators/python.py", line 117, in execute
    return_value = self.execute_callable()
  File "/Users/prathyusha/Desktop/pranathi/CSYE7245-Spring2021-Labs/transcript-simulated-api/airflow/edgar4_env/lib/python3.7/site-packages/airflow/operators/python.py", line 128, in execute_callable
    return self.python_callable(*self.op_args, **self.op_kwargs)
  File "/Users/prathyusha/Desktop/pranathi/CSYE7245-Spring2021-Labs/transcript-simulated-api/airflow/dags/edgar_inference.py", line 46, in download
    with urllib.request.urlopen("http://127.0.0.1:8000/call-transcripts/{}/2021".format(company)) as url:
  File "/Library/Frameworks/Python.framework/Versions/3.7/lib/python3.7/urllib/request.py", line 222, in urlopen
    return opener.open(url, data, timeout)
  File "/Library/Frameworks/Python.framework/Versions/3.7/lib/python3.7/urllib/request.py", line 525, in open
    response = self._open(req, data)
  File "/Library/Frameworks/Python.framework/Versions/3.7/lib/python3.7/urllib/request.py", line 543, in _open
    '_open', req)
  File "/Library/Frameworks/Python.framework/Versions/3.7/lib/python3.7/urllib/request.py", line 503, in _call_chain
    result = func(*args)
  File "/Library/Frameworks/Python.framework/Versions/3.7/lib/python3.7/urllib/request.py", line 1378, in http_open
    return self.do_open(http.client.HTTPConnection, req)
  File "/Library/Frameworks/Python.framework/Versions/3.7/lib/python3.7/urllib/request.py", line 1352, in do_open
    raise URLError(err)
urllib.error.URLError: <urlopen error [Errno 61] Connection refused>
[2021-03-25 14:18:49,513] {taskinstance.py:1503} INFO - Marking task as FAILED. dag_id=EDGAR-Inference-Pipeline, task_id=DownloadDataFromCloud, execution_date=20210325T000000, start_date=20210325T211849, end_date=20210325T211849
[2021-03-25 14:18:49,569] {local_task_job.py:146} INFO - Task exited with return code 1
